<mujoco model="example">
	<compiler coordinate="global"/>
	<default>
		<geom rgba=".8 .6 .4 1"/>
	</default>
	<asset>
		<texture type="skybox" builtin="gradient" rgb1="1 1 1" rgb2=".6 .8 1" width="256" height="256"/>
	</asset>
	<worldbody>
		<light pos="0 1 1" dir="0 -1 -1" diffuse="1 1 1"/>
		<body>
			<geom type="capsule" fromto="0 0 0  0 0 0.5" size=".05"/>
			<joint type="hinge" name="s_link1" pos="0 0 0" axis="0 1 0" damping="1"/>
			<body>
				<geom type="capsule" fromto="0 0 0.5  0 0 1.0" size=".05"/>
				<joint type="hinge" name="s_link2" pos="0 0 0.5" axis="0 1 0" damping="5"/>
			</body>
		</body>
	</worldbody>
	<actuator>	
		<motor joint='s_link2' name='As_link1' gear="1"/>
		<!-- <position joint='s_link' name='As_link' kp="10"/> -->
		<!-- <velocity joint='s_link' name='As_link' kv="100"/> -->
	</actuator>
</mujoco>